Workbook

Sheet Instrucciones
A1: Mini proyecto FinTech 2 — Calidad de datos (50 registros)
A3: Objetivo: limpiar textos inconsistentes, validar estatus y generar un reporte de calidad de datos.
A5: Paso | B5: Actividad
A6: 1 | B6: En Pagos_50_Limpio, limpia Nombre_Capturado (columna A) utilizando ESPACIOS y guarda el resultado en Nombre_Limpio (columna B)
A7: 2 | B7: En Pagos_50_Limpio, limpia Estatus_Capturado (columna F) utilizando ESPACIOS y guarda el resultado en Estatus_Limpio (columna G)
A8: 3 | B8: En Pagos_50_Limpio, valida Estatus_Limpio (columna G). Si el valor es Aprobada, Pendiente, Rechazada o Cancelada, registra "Válido" en Calidad_Estatus (columna H); de lo contrario, registra "Revisar"
A9: 4 | B9: En Pagos_50_Limpio, valida Monto (columna E). Si el monto está vacío o es menor o igual a 0, registra "Revisar" en Calidad_Monto (columna I); de lo contrario, registra "Válido"
A10: 5 | B10: En Pagos_50_Limpio, copia las fórmulas de las columnas B, G, H e I desde la fila 2 hasta la fila 51, para procesar los 50 registros
A11: 6 | B11: En la hoja Resumen, utiliza CONTAR.SI para calcular los estatus válidos, estatus por revisar, montos válidos, montos por revisar y pagos con estatus Cancelada. Comprueba que los resultados coincidan con los registros de Pagos_50_Limpio
A14: Fórmulas que practicarás
A15: ESPACIOS | B15: =ESPACIOS(A2)
A16: ESPACIOS estatus | B16: =ESPACIOS(F2)
A17: SI + O | B17: =SI(O(G2="Aprobada";G2="Pendiente";G2="Rechazada";G2="Cancelada");"Válido";"Revisar")
A18: SI + O monto | B18: =SI(O(E2="";E2<=0);"Revisar";"Válido")
A19: CONTAR.SI | B19: =CONTAR.SI(Pagos_50_Limpio!I2:I51;"Revisar")
A22: Este ejercicio se parece a Data Quality: no solo importa que la fórmula funcione, sino detectar datos que deben corregirse antes de usarlos en un reporte.

Sheet Resumen
A1: Reporte de calidad de datos
A3: Indicador | B3: Resultado | C3: Comprobación
A4: Estatus válidos | B4: =COUNTIF(Pagos_50_Limpio!H2:H51,"Válido") -> 50 | C4: =IF(B4=50,"Correcto","Revisa") -> Correcto
A5: Estatus por revisar | B5: =COUNTIF(Pagos_50_Limpio!H2:H51,"Revisar") -> 0 | C5: =IF(B5=0,"Correcto","Revisa") -> Correcto
A6: Montos válidos | B6: =COUNTIF(Pagos_50_Limpio!I2:I51,"Válido") -> 45 | C6: =IF(B6=45,"Correcto","Revisa") -> Correcto
A7: Montos por revisar | B7: =COUNTIF(Pagos_50_Limpio!I2:I51,"Revisar") -> 5 | C7: =IF(B7=5,"Correcto","Revisa") -> Correcto
A8: Pagos con estatus Cancelada | B8: =COUNTIF(Pagos_50_Limpio!G2:G51,"Cancelada") -> 6 | C8: =IF(B8=6,"Correcto","Revisa") -> Correcto
A11: Pistas
A12: 1. | B12: Estatus válidos: contar "Válido" en Pagos_50_Limpio!H2:H51
A13: 2. | B13: Estatus por revisar: contar "Revisar" en Pagos_50_Limpio!H2:H51
A14: 3. | B14: Montos válidos: contar "Válido" en Pagos_50_Limpio!I2:I51
A15: 4. | B15: Montos por revisar: contar "Revisar" en Pagos_50_Limpio!I2:I51
A16: 5. | B16: Pagos cancelados: contar "Cancelada" en Pagos_50_Limpio!G2:G51

Sheet Pagos_50_Original
A1: ID_Pago | B1: Nombre_Capturado | C1: Nombre_Limpio | D1: Fecha | E1: Producto_Financiero | F1: Monto | G1: Estatus_Capturado | H1: Calidad_Estatus | I1: Calidad_Monto | J1: Comprobación
A2: PAY-2026-0001 | B2: Ana López | C2: =TRIM(B2) -> Ana López | D2: 46204 | E2: Tarjeta crédito | F2: 461.75 | G2: Rechazada | H2: =IF(OR(E2<=0),"Revisar","Válido") -> Válido | I2: =IF(OR(E2="",E2=0),"Revisar","Valido") -> Valido | J2: =IF(AND(Pagos_50_Original!A2="Ana López", Pagos_50_Original!G2="Rechazada", H2="Válido", I2="Válido"), "Correcto", "Revisa") -> Revisa
A3: PAY-2026-0002 | B3: Carlos Ruiz | C3: =TRIM(B3) -> Carlos Ruiz | D3: 46205 | E3: Préstamo personal | F3: 673.5 | G3: RECHAZADA | H3: =IF(OR(E3<=0),"Revisar","Válido") -> Válido | I3: =IF(OR(E3="",E3=0),"Revisar","Valido") -> Valido | J3: =IF(AND(Pagos_50_Original!A3="Ana López", Pagos_50_Original!G3="Rechazada", H3="Válido", I3="Válido"), "Correcto", "Revisa") -> Revisa
A4: PAY-2026-0003 | B4: María Torres | C4: =TRIM(B4) -> María Torres | D4: 46206 | E4: Cuenta digital | F4: 883 | G4: Aprobada | H4: =IF(OR(E4<=0),"Revisar","Válido") -> Válido | I4: =IF(OR(E4="",E4=0),"Revisar","Valido") -> Valido | J4: =IF(AND(Pagos_50_Original!A4="Ana López", Pagos_50_Original!G4="Rechazada", H4="Válido", I4="Válido"), "Correcto", "Revisa") -> Revisa
A5: PAY-2026-0004 | B5: José Pérez | C5: =TRIM(B5) -> José Pérez | D5: 46207 | E5: Wallet | F5: 1094.75 | G5: Aprobada | H5: =IF(OR(E5<=0),"Revisar","Válido") -> Válido | I5: =IF(OR(E5="",E5=0),"Revisar","Valido") -> Valido | J5: =IF(AND(Pagos_50_Original!A5="Ana López", Pagos_50_Original!G5="Rechazada", H5="Válido", I5="Válido"), "Correcto", "Revisa") -> Revisa
A6: PAY-2026-0005 | B6: Laura Díaz | C6: =TRIM(B6) -> Laura Díaz | D6: 46208 | E6: Tarjeta crédito | F6: 1306.5 | G6: Cancelada | H6: =IF(OR(E6<=0),"Revisar","Válido") -> Válido | I6: =IF(OR(E6="",E6=0),"Revisar","Valido") -> Valido | J6: =IF(AND(Pagos_50_Original!A6="Ana López", Pagos_50_Original!G6="Rechazada", H6="Válido", I6="Válido"), "Correcto", "Revisa") -> Revisa
A7: PAY-2026-0006 | B7: Miguel Soto | C7: =TRIM(B7) -> Miguel Soto | D7: 46209 | E7: Préstamo personal | F7: 1516 | G7: Pendiente | H7: =IF(OR(E7<=0),"Revisar","Válido") -> Válido | I7: =IF(OR(E7="",E7=0),"Revisar","Valido") -> Valido | J7: =IF(AND(Pagos_50_Original!A7="Ana López", Pagos_50_Original!G7="Rechazada", H7="Válido", I7="Válido"), "Correcto", "Revisa") -> Revisa
A8: PAY-2026-0007 | B8: Sofía Ramos | C8: =TRIM(B8) -> Sofía Ramos | D8: 46210 | E8: Cuenta digital | F8: 1727.75 | G8: pendiente | H8: =IF(OR(E8<=0),"Revisar","Válido") -> Válido | I8: =IF(OR(E8="",E8=0),"Revisar","Valido") -> Valido | J8: =IF(AND(Pagos_50_Original!A8="Ana López", Pagos_50_Original!G8="Rechazada", H8="Válido", I8="Válido"), "Correcto", "Revisa") -> Revisa
A9: PAY-2026-0008 | B9: Daniel Cruz | C9: =TRIM(B9) -> Daniel Cruz | D9: 46211 | E9: Wallet | F9: 0 | G9: Aprobada | H9: =IF(OR(E9<=0),"Revisar","Válido") -> Válido | I9: =IF(OR(E9="",E9=0),"Revisar","Valido") -> Valido | J9: =IF(AND(Pagos_50_Original!A9="Ana López", Pagos_50_Original!G9="Rechazada", H9="Válido", I9="Válido"), "Correcto", "Revisa") -> Revisa
A10: PAY-2026-0009 | B10: Ana López | C10: =TRIM(B10) -> Ana López | D10: 46212 | E10: Tarjeta crédito | F10: 2149 | G10: Rechazada | H10: =IF(OR(E10<=0),"Revisar","Válido") -> Válido | I10: =IF(OR(E10="",E10=0),"Revisar","Valido") -> Valido | J10: =IF(AND(Pagos_50_Original!A10="Ana López", Pagos_50_Original!G10="Rechazada", H10="Válido", I10="Válido"), "Correcto", "Revisa") -> Revisa
A11: PAY-2026-0010 | B11: Carlos Ruiz | C11: =TRIM(B11) -> Carlos Ruiz | D11: 46213 | E11: Préstamo personal | F11: 2360.75 | G11: RECHAZADA | H11: =IF(OR(E11<=0),"Revisar","Válido") -> Válido | I11: =IF(OR(E11="",E11=0),"Revisar","Valido") -> Valido | J11: =IF(AND(Pagos_50_Original!A11="Ana López", Pagos_50_Original!G11="Rechazada", H11="Válido", I11="Válido"), "Correcto", "Revisa") -> Revisa
A12: PAY-2026-0011 | B12: María Torres | C12: =TRIM(B12) -> María Torres | D12: 46214 | E12: Cuenta digital | F12: 2572.5 | G12: Aprobada | H12: =IF(OR(E12<=0),"Revisar","Válido") -> Válido | I12: =IF(OR(E12="",E12=0),"Revisar","Valido") -> Valido | J12: =IF(AND(Pagos_50_Original!A12="Ana López", Pagos_50_Original!G12="Rechazada", H12="Válido", I12="Válido"), "Correcto", "Revisa") -> Revisa
A13: PAY-2026-0012 | B13: José Pérez | C13: =TRIM(B13) -> José Pérez | D13: 46215 | E13: Wallet | F13: 2782 | G13: Aprobada | H13: =IF(OR(E13<=0),"Revisar","Válido") -> Válido | I13: =IF(OR(E13="",E13=0),"Revisar","Valido") -> Valido | J13: =IF(AND(Pagos_50_Original!A13="Ana López", Pagos_50_Original!G13="Rechazada", H13="Válido", I13="Válido"), "Correcto", "Revisa") -> Revisa
... A17: PAY-2026-0016 | B17: Daniel Cruz | C17: =TRIM(B17) -> Daniel Cruz | D17: 46219 | E17: Wallet | F17: 3626.75 | G17: Aprobada | H17: =IF(OR(E17<=0),"Revisar","Válido") -> Válido | I17: =IF(OR(E17="",E17=0),"Revisar","Valido") -> Valido | J17: =IF(AND(Pagos_50_Original!A17="Ana López", Pagos_50_Original!G17="Rechazada", H17="Válido", I17="Válido"), "Correcto", "Revisa") -> Revisa
A18: PAY-2026-0017 | B18: Ana López | C18: =TRIM(B18) -> Ana López | D18: 46220 | E18: Tarjeta crédito | G18: Rechazada | H18: =IF(OR(E18<=0),"Revisar","Válido") -> Válido | I18: =IF(OR(E18="",E18=0),"Revisar","Valido") -> Valido | J18: =IF(AND(Pagos_50_Original!A18="Ana López", Pagos_50_Original!G18="Rechazada", H18="Válido", I18="Válido"), "Correcto", "Revisa") -> Revisa
A19: PAY-2026-0018 | B19: Carlos Ruiz | C19: =TRIM(B19) -> Carlos Ruiz | D19: 46221 | E19: Préstamo personal | F19: 4048 | G19: RECHAZADA | H19: =IF(OR(E19<=0),"Revisar","Válido") -> Válido | I19: =IF(OR(E19="",E19=0),"Revisar","Valido") -> Valido | J19: =IF(AND(Pagos_50_Original!A19="Ana López", Pagos_50_Original!G19="Rechazada", H19="Válido", I19="Válido"), "Correcto", "Revisa") -> Revisa
A20: PAY-2026-0019 | B20: María Torres | C20: =TRIM(B20) -> María Torres | D20: 46222 | E20: Cuenta digital | F20: 4259.75 | G20: Aprobada | H20: =IF(OR(E20<=0),"Revisar","Válido") -> Válido | I20: =IF(OR(E20="",E20=0),"Revisar","Valido") -> Valido | J20: =IF(AND(Pagos_50_Original!A20="Ana López", Pagos_50_Original!G20="Rechazada", H20="Válido", I20="Válido"), "Correcto", "Revisa") -> Revisa
A21: PAY-2026-0020 | B21: José Pérez | C21: =TRIM(B21) -> José Pérez | D21: 46223 | E21: Wallet | F21: 271.5 | G21: Aprobada | H21: =IF(OR(E21<=0),"Revisar","Válido") -> Válido | I21: =IF(OR(E21="",E21=0),"Revisar","Valido") -> Valido | J21: =IF(AND(Pagos_50_Original!A21="Ana López", Pagos_50_Original!G21="Rechazada", H21="Válido", I21="Válido"), "Correcto", "Revisa") -> Revisa
A22: PAY-2026-0021 | B22: Laura Díaz | C22: =TRIM(B22) -> Laura Díaz | D22: 46224 | E22: Tarjeta crédito | F22: 481 | G22: Cancelada | H22: =IF(OR(E22<=0),"Revisar","Válido") -> Válido | I22: =IF(OR(E22="",E22=0),"Revisar","Valido") -> Valido | J22: =IF(AND(Pagos_50_Original!A22="Ana López", Pagos_50_Original!G22="Rechazada", H22="Válido", I22="Válido"), "Correcto", "Revisa") -> Revisa
A23: PAY-2026-0022 | B23: Miguel Soto | C23: =TRIM(B23) -> Miguel Soto | D23: 46225 | E23: Préstamo personal | F23: 692.75 | G23: Pendiente | H23: =IF(OR(E23<=0),"Revisar","Válido") -> Válido | I23: =IF(OR(E23="",E23=0),"Revisar","Valido") -> Valido | J23: =IF(AND(Pagos_50_Original!A23="Ana López", Pagos_50_Original!G23="Rechazada", H23="Válido", I23="Válido"), "Correcto", "Revisa") -> Revisa
A24: PAY-2026-0023 | B24: Sofía Ramos | C24: =TRIM(B24) -> Sofía Ramos | D24: 46226 | E24: Cuenta digital | F24: 904.5 | G24: pendiente | H24: =IF(OR(E24<=0),"Revisar","Válido") -> Válido | I24: =IF(OR(E24="",E24=0),"Revisar","Valido") -> Valido | J24: =IF(AND(Pagos_50_Original!A24="Ana López", Pagos_50_Original!G24="Rechazada", H24="Válido", I24="Válido"), "Correcto", "Revisa") -> Revisa
A25: PAY-2026-0024 | B25: Daniel Cruz | C25: =TRIM(B25) -> Daniel Cruz | D25: 46227 | E25: Wallet | F25: 1114 | G25: Aprobada | H25: =IF(OR(E25<=0),"Revisar","Válido") -> Válido | I25: =IF(OR(E25="",E25=0),"Revisar","Valido") -> Valido | J25: =IF(AND(Pagos_50_Original!A25="Ana López", Pagos_50_Original!G25="Rechazada", H25="Válido", I25="Válido"), "Correcto", "Revisa") -> Revisa
A26: PAY-2026-0025 | B26: Ana López | C26: =TRIM(B26) -> Ana López | D26: 46228 | E26: Tarjeta crédito | F26: 1325.75 | G26: Rechazada | H26: =IF(OR(E26<=0),"Revisar","Válido") -> Válido | I26: =IF(OR(E26="",E26=0),"Revisar","Valido") -> Valido | J26: =IF(AND(Pagos_50_Original!A26="Ana López", Pagos_50_Original!G26="Rechazada", H26="Válido", I26="Válido"), "Correcto", "Revisa") -> Revisa
A27: PAY-2026-0026 | B27: Carlos Ruiz | C27: =TRIM(B27) -> Carlos Ruiz | D27: 46204 | E27: Préstamo personal | F27: 1537.5 | G27: RECHAZADA | H27: =IF(OR(E27<=0),"Revisar","Válido") -> Válido | I27: =IF(OR(E27="",E27=0),"Revisar","Valido") -> Valido | J27: =IF(AND(Pagos_50_Original!A27="Ana López", Pagos_50_Original!G27="Rechazada", H27="Válido", I27="Válido"), "Correcto", "Revisa") -> Revisa
A28: PAY-2026-0027 | B28: María Torres | C28: =TRIM(B28) -> María Torres | D28: 46205 | E28: Cuenta digital | F28: 1747 | G28: Aprobada | H28: =IF(OR(E28<=0),"Revisar","Válido") -> Válido | I28: =IF(OR(E28="",E28=0),"Revisar","Valido") -> Valido | J28: =IF(AND(Pagos_50_Original!A28="Ana López", Pagos_50_Original!G28="Rechazada", H28="Válido", I28="Válido"), "Correcto", "Revisa") -> Revisa
A29: PAY-2026-0028 | B29: José Pérez | C29: =TRIM(B29) -> José Pérez | D29: 46206 | E29: Wallet | F29: 1958.75 | G29: Aprobada | H29: =IF(OR(E29<=0),"Revisar","Válido") -> Válido | I29: =IF(OR(E29="",E29=0),"Revisar","Valido") -> Valido | J29: =IF(AND(Pagos_50_Original!A29="Ana López", Pagos_50_Original!G29="Rechazada", H29="Válido", I29="Válido"), "Correcto", "Revisa") -> Revisa
A30: PAY-2026-0029 | B30: Laura Díaz | C30: =TRIM(B30) -> Laura Díaz | D30: 46207 | E30: Tarjeta crédito | G30: Cancelada | H30: =IF(OR(E30<=0),"Revisar","Válido") -> Válido | I30: =IF(OR(E30="",E30=0),"Revisar","Valido") -> Valido | J30: =IF(AND(Pagos_50_Original!A30="Ana López", Pagos_50_Original!G30="Rechazada", H30="Válido", I30="Válido"), "Correcto", "Revisa") -> Revisa
A31: PAY-2026-0030 | B31: Miguel Soto | C31: =TRIM(B31) -> Miguel Soto | D31: 46208 | E31: Préstamo personal | F31: 2380 | G31: Pendiente | H31: =IF(OR(E31<=0),"Revisar","Válido") -> Válido | I31: =IF(OR(E31="",E31=0),"Revisar","Valido") -> Valido | J31: =IF(AND(Pagos_50_Original!A31="Ana López", Pagos_50_Original!G31="Rechazada", H31="Válido", I31="Válido"), "Correcto", "Revisa") -> Revisa
A32: PAY-2026-0031 | B32: Sofía Ramos | C32: =TRIM(B32) -> Sofía Ramos | D32: 46209 | E32: Cuenta digital | F32: 2591.75 | G32: pendiente | H32: =IF(OR(E32<=0),"Revisar","Válido") -> Válido | I32: =IF(OR(E32="",E32=0),"Revisar","Valido") -> Valido | J32: =IF(AND(Pagos_50_Original!A32="Ana López", Pagos_50_Original!G32="Rechazada", H32="Válido", I32="Válido"), "Correcto", "Revisa") -> Revisa
A33: PAY-2026-0032 | B33: Daniel Cruz | C33: =TRIM(B33) -> Daniel Cruz | D33: 46210 | E33: Wallet | F33: 2803.5 | G33: Aprobada | H33: =IF(OR(E33<=0),"Revisar","Válido") -> Válido | I33: =IF(OR(E33="",E33=0),"Revisar","Valido") -> Valido | J33: =IF(AND(Pagos_50_Original!A33="Ana López", Pagos_50_Original!G33="Rechazada", H33="Válido", I33="Válido"), "Correcto", "Revisa") -> Revisa
A34: PAY-2026-0033 | B34: Ana López | C34: =TRIM(B34) -> Ana López | D34: 46211 | E34: Tarjeta crédito | F34: 3013 | G34: Rechazada | H34: =IF(OR(E34<=0),"Revisar","Válido") -> Válido | I34: =IF(OR(E34="",E34=0),"Revisar","Valido") -> Valido | J34: =IF(AND(Pagos_50_Original!A34="Ana López", Pagos_50_Original!G34="Rechazada", H34="Válido", I34="Válido"), "Correcto", "Revisa") -> Revisa
A35: PAY-2026-0034 | B35: Carlos Ruiz | C35: =TRIM(B35) -> Carlos Ruiz | D35: 46212 | E35: Préstamo personal | F35: 3224.75 | G35: RECHAZADA | H35: =IF(OR(E35<=0),"Revisar","Válido") -> Válido | I35: =IF(OR(E35="",E35=0),"Revisar","Valido") -> Valido | J35: =IF(AND(Pagos_50_Original!A35="Ana López", Pagos_50_Original!G35="Rechazada", H35="Válido", I35="Válido"), "Correcto", "Revisa") -> Revisa
A36: PAY-2026-0035 | B36: María Torres | C36: =TRIM(B36) -> María Torres | D36: 46213 | E36: Cuenta digital | F36: 3436.5 | G36: Aprobada | H36: =IF(OR(E36<=0),"Revisar","Válido") -> Válido | I36: =IF(OR(E36="",E36=0),"Revisar","Valido") -> Valido | J36: =IF(AND(Pagos_50_Original!A36="Ana López", Pagos_50_Original!G36="Rechazada", H36="Válido", I36="Válido"), "Correcto", "Revisa") -> Revisa
A37: PAY-2026-0036 | B37: José Pérez | C37: =TRIM(B37) -> José Pérez | D37: 46214 | E37: Wallet | F37: 3646 | G37: Aprobada | H37: =IF(OR(E37<=0),"Revisar","Válido") -> Válido | I37: =IF(OR(E37="",E37=0),"Revisar","Valido") -> Valido | J37: =IF(AND(Pagos_50_Original!A37="Ana López", Pagos_50_Original!G37="Rechazada", H37="Válido", I37="Válido"), "Correcto", "Revisa") -> Revisa
A38: PAY-2026-0037 | B38: Laura Díaz | C38: =TRIM(B38) -> Laura Díaz | D38: 46215 | E38: Tarjeta crédito | F38: 3857.75 | G38: Cancelada | H38: =IF(OR(E38<=0),"Revisar","Válido") -> Válido | I38: =IF(OR(E38="",E38=0),"Revisar","Valido") -> Valido | J38: =IF(AND(Pagos_50_Original!A38="Ana López", Pagos_50_Original!G38="Rechazada", H38="Válido", I38="Válido"), "Correcto", "Revisa") -> Revisa
A39: PAY-2026-0038 | B39: Miguel Soto | C39: =TRIM(B39) -> Miguel Soto | D39: 46216 | E39: Préstamo personal | F39: 4069.5 | G39: Pendiente | H39: =IF(OR(E39<=0),"Revisar","Válido") -> Válido | I39: =IF(OR(E39="",E39=0),"Revisar","Valido") -> Valido | J39: =IF(AND(Pagos_50_Original!A39="Ana López", Pagos_50_Original!G39="Rechazada", H39="Válido", I39="Válido"), "Correcto", "Revisa") -> Revisa
A40: PAY-2026-0039 | B40: Sofía Ramos | C40: =TRIM(B40) -> Sofía Ramos | D40: 46217 | E40: Cuenta digital | F40: 4279 | G40: pendiente | H40: =IF(OR(E40<=0),"Revisar","Válido") -> Válido | I40: =IF(OR(E40="",E40=0),"Revisar","Valido") -> Valido | J40: =IF(AND(Pagos_50_Original!A40="Ana López", Pagos_50_Original!G40="Rechazada", H40="Válido", I40="Válido"), "Correcto", "Revisa") -> Revisa
A41: PAY-2026-0040 | B41: Daniel Cruz | C41: =TRIM(B41) -> Daniel Cruz | D41: 46218 | E41: Wallet | F41: 290.75 | G41: Aprobada | H41: =IF(OR(E41<=0),"Revisar","Válido") -> Válido | I41: =IF(OR(E41="",E41=0),"Revisar","Valido") -> Valido | J41: =IF(AND(Pagos_50_Original!A41="Ana López", Pagos_50_Original!G41="Rechazada", H41="Válido", I41="Válido"), "Correcto", "Revisa") -> Revisa
A42: PAY-2026-0041 | B42: Ana López | C42: =TRIM(B42) -> Ana López | D42: 46219 | E42: Tarjeta crédito | G42: Rechazada | H42: =IF(OR(E42<=0),"Revisar","Válido") -> Válido | I42: =IF(OR(E42="",E42=0),"Revisar","Valido") -> Valido | J42: =IF(AND(Pagos_50_Original!A42="Ana López", Pagos_50_Original!G42="Rechazada", H42="Válido", I42="Válido"), "Correcto", "Revisa") -> Revisa
A43: PAY-2026-0042 | B43: Carlos Ruiz | C43: =TRIM(B43) -> Carlos Ruiz | D43: 46220 | E43: Préstamo personal | F43: 712 | G43: RECHAZADA | H43: =IF(OR(E43<=0),"Revisar","Válido") -> Válido | I43: =IF(OR(E43="",E43=0),"Revisar","Valido") -> Valido | J43: =IF(AND(Pagos_50_Original!A43="Ana López", Pagos_50_Original!G43="Rechazada", H43="Válido", I43="Válido"), "Correcto", "Revisa") -> Revisa
...

Sheet Pagos_50_Limpio
A1: Nombre_Capturado | B1: Nombre_Limpio | C1: Fecha | D1: Producto_Financiero | E1: Monto | F1: Estatus_Capturado | G1: Estatus_Limpio | H1: Calidad_Estatus | I1: Calidad_Monto | J1: Comprobación
A2: Ana López | B2: =TRIM(A2) -> Ana López | C2: 46204 | D2: Tarjeta crédito | E2: 461.75 | F2: Rechazada | G2: =TRIM(F2) -> Rechazada | H2: =IF(OR(G2="Aprobada",G2="Rechazada",G2="Pendiente",G2="Cancelada"),"Válido","Revisar") -> Válido | I2: =IF(OR(E2="",E2=0),"Revisar","Válido") -> Válido | J2: =IF(H2<>"Válido","Revisa",IF(I2<>"Válido","Revisa","Correcto")) -> Correcto
A3: Carlos Ruiz | B3: =TRIM(A3) -> Carlos Ruiz | C3: 46205 | D3: Préstamo personal | E3: 673.5 | F3: RECHAZADA | G3: =TRIM(F3) -> RECHAZADA | H3: =IF(OR(G3="Aprobada",G3="Rechazada",G3="Pendiente",G3="Cancelada"),"Válido","Revisar") -> Válido | I3: =IF(OR(E3="",E3=0),"Revisar","Válido") -> Válido | J3: =IF(H3<>"Válido","Revisa",IF(I3<>"Válido","Revisa","Correcto")) -> Correcto
A4: María Torres | B4: =TRIM(A4) -> María Torres | C4: 46206 | D4: Cuenta digital | E4: 883 | F4: Aprobada | G4: =TRIM(F4) -> Aprobada | H4: =IF(OR(G4="Aprobada",G4="Rechazada",G4="Pendiente",G4="Cancelada"),"Válido","Revisar") -> Válido | I4: =IF(OR(E4="",E4=0),"Revisar","Válido") -> Válido | J4: =IF(H4<>"Válido","Revisa",IF(I4<>"Válido","Revisa","Correcto")) -> Correcto
A5: José Pérez | B5: =TRIM(A5) -> José Pérez | C5: 46207 | D5: Wallet | E5: 1094.75 | F5: Aprobada | G5: =TRIM(F5) -> Aprobada | H5: =IF(OR(G5="Aprobada",G5="Rechazada",G5="Pendiente",G5="Cancelada"),"Válido","Revisar") -> Válido | I5: =IF(OR(E5="",E5=0),"Revisar","Válido") -> Válido | J5: =IF(H5<>"Válido","Revisa",IF(I5<>"Válido","Revisa","Correcto")) -> Correcto
A6: Laura Díaz | B6: =TRIM(A6) -> Laura Díaz | C6: 46208 | D6: Tarjeta crédito | E6: 1306.5 | F6: Cancelada | G6: =TRIM(F6) -> Cancelada | H6: =IF(OR(G6="Aprobada",G6="Rechazada",G6="Pendiente",G6="Cancelada"),"Válido","Revisar") -> Válido | I6: =IF(OR(E6="",E6=0),"Revisar","Válido") -> Válido | J6: =IF(H6<>"Válido","Revisa",IF(I6<>"Válido","Revisa","Correcto")) -> Correcto
A7: Miguel Soto | B7: =TRIM(A7) -> Miguel Soto | C7: 46209 | D7: Préstamo personal | E7: 1516 | F7: Pendiente | G7: =TRIM(F7) -> Pendiente | H7: =IF(OR(G7="Aprobada",G7="Rechazada",G7="Pendiente",G7="Cancelada"),"Válido","Revisar") -> Válido | I7: =IF(OR(E7="",E7=0),"Revisar","Válido") -> Válido | J7: =IF(H7<>"Válido","Revisa",IF(I7<>"Válido","Revisa","Correcto")) -> Correcto
A8: Sofía Ramos | B8: =TRIM(A8) -> Sofía Ramos | C8: 46210 | D8: Cuenta digital | E8: 1727.75 | F8: pendiente | G8: =TRIM(F8) -> pendiente | H8: =IF(OR(G8="Aprobada",G8="Rechazada",G8="Pendiente",G8="Cancelada"),"Válido","Revisar") -> Válido | I8: =IF(OR(E8="",E8=0),"Revisar","Válido") -> Válido | J8: =IF(H8<>"Válido","Revisa",IF(I8<>"Válido","Revisa","Correcto")) -> Correcto
A9: Daniel Cruz | B9: =TRIM(A9) -> Daniel Cruz | C9: 46211 | D9: Wallet | E9: 0 | F9: Aprobada | G9: =TRIM(F9) -> Aprobada | H9: =IF(OR(G9="Aprobada",G9="Rechazada",G9="Pendiente",G9="Cancelada"),"Válido","Revisar") -> Válido | I9: =IF(OR(E9="",E9=0),"Revisar","Válido") -> Revisar | J9: =IF(H9<>"Válido","Revisa",IF(I9<>"Válido","Revisa","Correcto")) -> Revisa
A10: Ana López | B10: =TRIM(A10) -> Ana López | C10: 46212 | D10: Tarjeta crédito | E10: 2149 | F10: Rechazada | G10: =TRIM(F10) -> Rechazada | H10: =IF(OR(G10="Aprobada",G10="Rechazada",G10="Pendiente",G10="Cancelada"),"Válido","Revisar") -> Válido | I10: =IF(OR(E10="",E10=0),"Revisar","Válido") -> Válido | J10: =IF(H10<>"Válido","Revisa",IF(I10<>"Válido","Revisa","Correcto")) -> Correcto
A11: Carlos Ruiz | B11: =TRIM(A11) -> Carlos Ruiz | C11: 46213 | D11: Préstamo personal | E11: 2360.75 | F11: RECHAZADA | G11: =TRIM(F11) -> RECHAZADA | H11: =IF(OR(G11="Aprobada",G11="Rechazada",G11="Pendiente",G11="Cancelada"),"Válido","Revisar") -> Válido | I11: =IF(OR(E11="",E11=0),"Revisar","Válido") -> Válido | J11: =IF(H11<>"Válido","Revisa",IF(I11<>"Válido","Revisa","Correcto")) -> Correcto
A12: María Torres | B12: =TRIM(A12) -> María Torres | C12: 46214 | D12: Cuenta digital | E12: 2572.5 | F12: Aprobada | G12: =TRIM(F12) -> Aprobada | H12: =IF(OR(G12="Aprobada",G12="Rechazada",G12="Pendiente",G12="Cancelada"),"Válido","Revisar") -> Válido | I12: =IF(OR(E12="",E12=0),"Revisar","Válido") -> Válido | J12: =IF(H12<>"Válido","Revisa",IF(I12<>"Válido","Revisa","Correcto")) -> Correcto
A13: José Pérez | B13: =TRIM(A13) -> José Pérez | C13: 46215 | D13: Wallet | E13: 2782 | F13: Aprobada | G13: =TRIM(F13) -> Aprobada | H13: =IF(OR(G13="Aprobada",G13="Rechazada",G13="Pendiente",G13="Cancelada"),"Válido","Revisar") -> Válido | I13: =IF(OR(E13="",E13=0),"Revisar","Válido") -> Válido | J13: =IF(H13<>"Válido","Revisa",IF(I13<>"Válido","Revisa","Correcto")) -> Correcto
... A17: Daniel Cruz | B17: =TRIM(A17) -> Daniel Cruz | C17: 46219 | D17: Wallet | E17: 3626.75 | F17: Aprobada | G17: =TRIM(F17) -> Aprobada | H17: =IF(OR(G17="Aprobada",G17="Rechazada",G17="Pendiente",G17="Cancelada"),"Válido","Revisar") -> Válido | I17: =IF(OR(E17="",E17=0),"Revisar","Válido") -> Válido | J17: =IF(H17<>"Válido","Revisa",IF(I17<>"Válido","Revisa","Correcto")) -> Correcto
A18: Ana López | B18: =TRIM(A18) -> Ana López | C18: 46220 | D18: Tarjeta crédito | F18: Rechazada | G18: =TRIM(F18) -> Rechazada | H18: =IF(OR(G18="Aprobada",G18="Rechazada",G18="Pendiente",G18="Cancelada"),"Válido","Revisar") -> Válido | I18: =IF(OR(E18="",E18=0),"Revisar","Válido") -> Revisar | J18: =IF(H18<>"Válido","Revisa",IF(I18<>"Válido","Revisa","Correcto")) -> Revisa
A19: Carlos Ruiz | B19: =TRIM(A19) -> Carlos Ruiz | C19: 46221 | D19: Préstamo personal | E19: 4048 | F19: RECHAZADA | G19: =TRIM(F19) -> RECHAZADA | H19: =IF(OR(G19="Aprobada",G19="Rechazada",G19="Pendiente",G19="Cancelada"),"Válido","Revisar") -> Válido | I19: =IF(OR(E19="",E19=0),"Revisar","Válido") -> Válido | J19: =IF(H19<>"Válido","Revisa",IF(I19<>"Válido","Revisa","Correcto")) -> Correcto
A20: María Torres | B20: =TRIM(A20) -> María Torres | C20: 46222 | D20: Cuenta digital | E20: 4259.75 | F20: Aprobada | G20: =TRIM(F20) -> Aprobada | H20: =IF(OR(G20="Aprobada",G20="Rechazada",G20="Pendiente",G20="Cancelada"),"Válido","Revisar") -> Válido | I20: =IF(OR(E20="",E20=0),"Revisar","Válido") -> Válido | J20: =IF(H20<>"Válido","Revisa",IF(I20<>"Válido","Revisa","Correcto")) -> Correcto
A21: José Pérez | B21: =TRIM(A21) -> José Pérez | C21: 46223 | D21: Wallet | E21: 271.5 | F21: Aprobada | G21: =TRIM(F21) -> Aprobada | H21: =IF(OR(G21="Aprobada",G21="Rechazada",G21="Pendiente",G21="Cancelada"),"Válido","Revisar") -> Válido | I21: =IF(OR(E21="",E21=0),"Revisar","Válido") -> Válido | J21: =IF(H21<>"Válido","Revisa",IF(I21<>"Válido","Revisa","Correcto")) -> Correcto
A22: Laura Díaz | B22: =TRIM(A22) -> Laura Díaz | C22: 46224 | D22: Tarjeta crédito | E22: 481 | F22: Cancelada | G22: =TRIM(F22) -> Cancelada | H22: =IF(OR(G22="Aprobada",G22="Rechazada",G22="Pendiente",G22="Cancelada"),"Válido","Revisar") -> Válido | I22: =IF(OR(E22="",E22=0),"Revisar","Válido") -> Válido | J22: =IF(H22<>"Válido","Revisa",IF(I22<>"Válido","Revisa","Correcto")) -> Correcto
A23: Miguel Soto | B23: =TRIM(A23) -> Miguel Soto | C23: 46225 | D23: Préstamo personal | E23: 692.75 | F23: Pendiente | G23: =TRIM(F23) -> Pendiente | H23: =IF(OR(G23="Aprobada",G23="Rechazada",G23="Pendiente",G23="Cancelada"),"Válido","Revisar") -> Válido | I23: =IF(OR(E23="",E23=0),"Revisar","Válido") -> Válido | J23: =IF(H23<>"Válido","Revisa",IF(I23<>"Válido","Revisa","Correcto")) -> Correcto
A24: Sofía Ramos | B24: =TRIM(A24) -> Sofía Ramos | C24: 46226 | D24: Cuenta digital | E24: 904.5 | F24: pendiente | G24: =TRIM(F24) -> pendiente | H24: =IF(OR(G24="Aprobada",G24="Rechazada",G24="Pendiente",G24="Cancelada"),"Válido","Revisar") -> Válido | I24: =IF(OR(E24="",E24=0),"Revisar","Válido") -> Válido | J24: =IF(H24<>"Válido","Revisa",IF(I24<>"Válido","Revisa","Correcto")) -> Correcto
A25: Daniel Cruz | B25: =TRIM(A25) -> Daniel Cruz | C25: 46227 | D25: Wallet | E25: 1114 | F25: Aprobada | G25: =TRIM(F25) -> Aprobada | H25: =IF(OR(G25="Aprobada",G25="Rechazada",G25="Pendiente",G25="Cancelada"),"Válido","Revisar") -> Válido | I25: =IF(OR(E25="",E25=0),"Revisar","Válido") -> Válido | J25: =IF(H25<>"Válido","Revisa",IF(I25<>"Válido","Revisa","Correcto")) -> Correcto
A26: Ana López | B26: =TRIM(A26) -> Ana López | C26: 46228 | D26: Tarjeta crédito | E26: 1325.75 | F26: Rechazada | G26: =TRIM(F26) -> Rechazada | H26: =IF(OR(G26="Aprobada",G26="Rechazada",G26="Pendiente",G26="Cancelada"),"Válido","Revisar") -> Válido | I26: =IF(OR(E26="",E26=0),"Revisar","Válido") -> Válido | J26: =IF(H26<>"Válido","Revisa",IF(I26<>"Válido","Revisa","Correcto")) -> Correcto
A27: Carlos Ruiz | B27: =TRIM(A27) -> Carlos Ruiz | C27: 46204 | D27: Préstamo personal | E27: 1537.5 | F27: RECHAZADA | G27: =TRIM(F27) -> RECHAZADA | H27: =IF(OR(G27="Aprobada",G27="Rechazada",G27="Pendiente",G27="Cancelada"),"Válido","Revisar") -> Válido | I27: =IF(OR(E27="",E27=0),"Revisar","Válido") -> Válido | J27: =IF(H27<>"Válido","Revisa",IF(I27<>"Válido","Revisa","Correcto")) -> Correcto
A28: María Torres | B28: =TRIM(A28) -> María Torres | C28: 46205 | D28: Cuenta digital | E28: 1747 | F28: Aprobada | G28: =TRIM(F28) -> Aprobada | H28: =IF(OR(G28="Aprobada",G28="Rechazada",G28="Pendiente",G28="Cancelada"),"Válido","Revisar") -> Válido | I28: =IF(OR(E28="",E28=0),"Revisar","Válido") -> Válido | J28: =IF(H28<>"Válido","Revisa",IF(I28<>"Válido","Revisa","Correcto")) -> Correcto
A29: José Pérez | B29: =TRIM(A29) -> José Pérez | C29: 46206 | D29: Wallet | E29: 1958.75 | F29: Aprobada | G29: =TRIM(F29) -> Aprobada | H29: =IF(OR(G29="Aprobada",G29="Rechazada",G29="Pendiente",G29="Cancelada"),"Válido","Revisar") -> Válido | I29: =IF(OR(E29="",E29=0),"Revisar","Válido") -> Válido | J29: =IF(H29<>"Válido","Revisa",IF(I29<>"Válido","Revisa","Correcto")) -> Correcto
A30: Laura Díaz | B30: =TRIM(A30) -> Laura Díaz | C30: 46207 | D30: Tarjeta crédito | F30: Cancelada | G30: =TRIM(F30) -> Cancelada | H30: =IF(OR(G30="Aprobada",G30="Rechazada",G30="Pendiente",G30="Cancelada"),"Válido","Revisar") -> Válido | I30: =IF(OR(E30="",E30=0),"Revisar","Válido") -> Revisar | J30: =IF(H30<>"Válido","Revisa",IF(I30<>"Válido","Revisa","Correcto")) -> Revisa
A31: Miguel Soto | B31: =TRIM(A31) -> Miguel Soto | C31: 46208 | D31: Préstamo personal | E31: 2380 | F31: Pendiente | G31: =TRIM(F31) -> Pendiente | H31: =IF(OR(G31="Aprobada",G31="Rechazada",G31="Pendiente",G31="Cancelada"),"Válido","Revisar") -> Válido | I31: =IF(OR(E31="",E31=0),"Revisar","Válido") -> Válido | J31: =IF(H31<>"Válido","Revisa",IF(I31<>"Válido","Revisa","Correcto")) -> Correcto
A32: Sofía Ramos | B32: =TRIM(A32) -> Sofía Ramos | C32: 46209 | D32: Cuenta digital | E32: 2591.75 | F32: pendiente | G32: =TRIM(F32) -> pendiente | H32: =IF(OR(G32="Aprobada",G32="Rechazada",G32="Pendiente",G32="Cancelada"),"Válido","Revisar") -> Válido | I32: =IF(OR(E32="",E32=0),"Revisar","Válido") -> Válido | J32: =IF(H32<>"Válido","Revisa",IF(I32<>"Válido","Revisa","Correcto")) -> Correcto
A33: Daniel Cruz | B33: =TRIM(A33) -> Daniel Cruz | C33: 46210 | D33: Wallet | E33: 2803.5 | F33: Aprobada | G33: =TRIM(F33) -> Aprobada | H33: =IF(OR(G33="Aprobada",G33="Rechazada",G33="Pendiente",G33="Cancelada"),"Válido","Revisar") -> Válido | I33: =IF(OR(E33="",E33=0),"Revisar","Válido") -> Válido | J33: =IF(H33<>"Válido","Revisa",IF(I33<>"Válido","Revisa","Correcto")) -> Correcto
A34: Ana López | B34: =TRIM(A34) -> Ana López | C34: 46211 | D34: Tarjeta crédito | E34: 3013 | F34: Rechazada | G34: =TRIM(F34) -> Rechazada | H34: =IF(OR(G34="Aprobada",G34="Rechazada",G34="Pendiente",G34="Cancelada"),"Válido","Revisar") -> Válido | I34: =IF(OR(E34="",E34=0),"Revisar","Válido") -> Válido | J34: =IF(H34<>"Válido","Revisa",IF(I34<>"Válido","Revisa","Correcto")) -> Correcto
A35: Carlos Ruiz | B35: =TRIM(A35) -> Carlos Ruiz | C35: 46212 | D35: Préstamo personal | E35: 3224.75 | F35: RECHAZADA | G35: =TRIM(F35) -> RECHAZADA | H35: =IF(OR(G35="Aprobada",G35="Rechazada",G35="Pendiente",G35="Cancelada"),"Válido","Revisar") -> Válido | I35: =IF(OR(E35="",E35=0),"Revisar","Válido") -> Válido | J35: =IF(H35<>"Válido","Revisa",IF(I35<>"Válido","Revisa","Correcto")) -> Correcto
A36: María Torres | B36: =TRIM(A36) -> María Torres | C36: 46213 | D36: Cuenta digital | E36: 3436.5 | F36: Aprobada | G36: =TRIM(F36) -> Aprobada | H36: =IF(OR(G36="Aprobada",G36="Rechazada",G36="Pendiente",G36="Cancelada"),"Válido","Revisar") -> Válido | I36: =IF(OR(E36="",E36=0),"Revisar","Válido") -> Válido | J36: =IF(H36<>"Válido","Revisa",IF(I36<>"Válido","Revisa","Correcto")) -> Correcto
A37: José Pérez | B37: =TRIM(A37) -> José Pérez | C37: 46214 | D37: Wallet | E37: 3646 | F37: Aprobada | G37: =TRIM(F37) -> Aprobada | H37: =IF(OR(G37="Aprobada",G37="Rechazada",G37="Pendiente",G37="Cancelada"),"Válido","Revisar") -> Válido | I37: =IF(OR(E37="",E37=0),"Revisar","Válido") -> Válido | J37: =IF(H37<>"Válido","Revisa",IF(I37<>"Válido","Revisa","Correcto")) -> Correcto
A38: Laura Díaz | B38: =TRIM(A38) -> Laura Díaz | C38: 46215 | D38: Tarjeta crédito | E38: 3857.75 | F38: Cancelada | G38: =TRIM(F38) -> Cancelada | H38: =IF(OR(G38="Aprobada",G38="Rechazada",G38="Pendiente",G38="Cancelada"),"Válido","Revisar") -> Válido | I38: =IF(OR(E38="",E38=0),"Revisar","Válido") -> Válido | J38: =IF(H38<>"Válido","Revisa",IF(I38<>"Válido","Revisa","Correcto")) -> Correcto
A39: Miguel Soto | B39: =TRIM(A39) -> Miguel Soto | C39: 46216 | D39: Préstamo personal | E39: 4069.5 | F39: Pendiente | G39: =TRIM(F39) -> Pendiente | H39: =IF(OR(G39="Aprobada",G39="Rechazada",G39="Pendiente",G39="Cancelada"),"Válido","Revisar") -> Válido | I39: =IF(OR(E39="",E39=0),"Revisar","Válido") -> Válido | J39: =IF(H39<>"Válido","Revisa",IF(I39<>"Válido","Revisa","Correcto")) -> Correcto
A40: Sofía Ramos | B40: =TRIM(A40) -> Sofía Ramos | C40: 46217 | D40: Cuenta digital | E40: 4279 | F40: pendiente | G40: =TRIM(F40) -> pendiente | H40: =IF(OR(G40="Aprobada",G40="Rechazada",G40="Pendiente",G40="Cancelada"),"Válido","Revisar") -> Válido | I40: =IF(OR(E40="",E40=0),"Revisar","Válido") -> Válido | J40: =IF(H40<>"Válido","Revisa",IF(I40<>"Válido","Revisa","Correcto")) -> Correcto
A41: Daniel Cruz | B41: =TRIM(A41) -> Daniel Cruz | C41: 46218 | D41: Wallet | E41: 290.75 | F41: Aprobada | G41: =TRIM(F41) -> Aprobada | H41: =IF(OR(G41="Aprobada",G41="Rechazada",G41="Pendiente",G41="Cancelada"),"Válido","Revisar") -> Válido | I41: =IF(OR(E41="",E41=0),"Revisar","Válido") -> Válido | J41: =IF(H41<>"Válido","Revisa",IF(I41<>"Válido","Revisa","Correcto")) -> Correcto
A42: Ana López | B42: =TRIM(A42) -> Ana López | C42: 46219 | D42: Tarjeta crédito | F42: Rechazada | G42: =TRIM(F42) -> Rechazada | H42: =IF(OR(G42="Aprobada",G42="Rechazada",G42="Pendiente",G42="Cancelada"),"Válido","Revisar") -> Válido | I42: =IF(OR(E42="",E42=0),"Revisar","Válido") -> Revisar | J42: =IF(H42<>"Válido","Revisa",IF(I42<>"Válido","Revisa","Correcto")) -> Revisa
A43: Carlos Ruiz | B43: =TRIM(A43) -> Carlos Ruiz | C43: 46220 | D43: Préstamo personal | E43: 712 | F43: RECHAZADA | G43: =TRIM(F43) -> RECHAZADA | H43: =IF(OR(G43="Aprobada",G43="Rechazada",G43="Pendiente",G43="Cancelada"),"Válido","Revisar") -> Válido | I43: =IF(OR(E43="",E43=0),"Revisar","Válido") -> Válido | J43: =IF(H43<>"Válido","Revisa",IF(I43<>"Válido","Revisa","Correcto")) -> Correcto
...

Sheet Hallazgos
A1: Fila Origen | B1: Tipo de Hallazgo | C1: Valor Encontrado | D1: Observación | E1: Acción_Recomendada
A2: Fila 9 | B2: Monto de $0.00 | C2: 0 | D2: El monto esta en ceros | E2: Confirmar si el monto de $0.00 es válido para esta operación
A3: Fila 18 | B3: Monto vacío | C3: En blanco | D3: El monto no fue proporcionado | E3: Solicitar al cliente el monto correspondiente o confirmar si debe permanecer vacío
A4: Fila 30 | B4: Monto vacío | C4: En blanco | D4: El monto no fue proporcionado | E4: Solicitar al cliente el monto correspondiente o confirmar si debe permanecer vacío
A5: Fila 42 | B5: Monto vacío | C5: En blanco | D5: El monto no fue proporcionado | E5: Solicitar al cliente el monto correspondiente o confirmar si debe permanecer vacío
A6: Fila 49 | B6: Monto de $0.00 | C6: 0 | D6: El monto esta en ceros | E6: Confirmar si el monto de $0.00 es válido para esta operación

Sheet Solución
A1: Solución — revisa después de intentarlo
A3: Ubicación | B3: Fórmula | C3: Función | D3: Acción
A4: Pagos_50_Limpio!B2 | B4: =ESPACIOS(A2) | C4: Limpieza nombre | D4: Copiar hasta B51
A5: Pagos_50_Limpio!G2 | B5: =ESPACIOS(F2) | C5: Limpieza estatus | D5: Copiar hasta G51
A6: Pagos_50_Limpio!H2 | B6: =SI(O(G2="Aprobada";G2="Pendiente";G2="Rechazada";G2="Cancelada");"Válido";"Revisar") | C6: Validación estatus | D6: Copiar hasta H51
A7: Pagos_50_Limpio!I2 | B7: =SI(O(E2="";E2<=0);"Revisar";"Válido") | C7: Validación monto | D7: Copiar hasta I51
A8: Resumen!B4 | B8: =CONTAR.SI(Pagos_50_Limpio!H2:H51;"Válido") | C8: Resumen | D8: Una fórmula
A9: Resumen!B5 | B9: =CONTAR.SI(Pagos_50_Limpio!H2:H51;"Revisar") | C9: Resumen | D9: Una fórmula
A10: Resumen!B6 | B10: =CONTAR.SI(Pagos_50_Limpio!I2:I51;"Válido") | C10: Resumen | D10: Una fórmula
A11: Resumen!B7 | B11: =CONTAR.SI(Pagos_50_Limpio!I2:I51;"Revisar") | C11: Resumen | D11: Una fórmula
A12: Resumen!B8 | B12: =CONTAR.SI(Pagos_50_Limpio!G2:G51;"Cancelada") | C12: Resumen | D12: Una fórmula
